<?xml version="1.0" encoding="utf-8"?>
<!-- This URDF was automatically created by SolidWorks to URDF Exporter! Originally created by Stephen Brawner (brawner@gmail.com) 
     Commit Version: 1.6.0-4-g7f85cfe  Build Version: 1.6.7995.38578
     For more information, please see http://wiki.ros.org/sw_urdf_exporter -->
<robot
  name="simple_mtm">
  <link
    name="base_link">
    <inertial>
      <origin
        xyz="5.47327296421834E-12 0.121119699522857 -0.0331941103362252"
        rpy="0 0 0" />
      <mass
        value="1.10120945723253" />
      <inertia
        ixx="0.00778946719068149"
        ixy="-7.15589413625176E-15"
        ixz="1.5508964020848E-14"
        iyy="0.00283497412761363"
        iyz="6.01985020734694E-07"
        izz="0.00613139149583515" />
    </inertial>
    <visual>
      <origin
        xyz="0 0 0"
        rpy="0 0 0" />
      <geometry>
        <mesh
          filename="package://simple_mtm/meshes/visual/base_link.STL" />
      </geometry>
      <material
        name="">
        <color
          rgba="0.752941176470588 0.752941176470588 0.752941176470588 1" />
      </material>
    </visual>
    <collision>
      <origin
        xyz="0 0 0"
        rpy="0 0 0" />
      <geometry>
        <mesh
          filename="package://simple_mtm/meshes/visual/base_link.STL" />
      </geometry>
    </collision>
  </link>
  <link
    name="shoulder_link">
    <inertial>
      <origin
        xyz="-0.0272468695894675 -0.00431240065016392 0.0153287795195525"
        rpy="0 0 0" />
      <mass
        value="0.217265275235422" />
      <inertia
        ixx="8.82896590344558E-05"
        ixy="-5.23751752562606E-06"
        ixz="4.84630855564966E-07"
        iyy="9.8833829220296E-05"
        iyz="3.16058629158509E-07"
        izz="0.000161817798154812" />
    </inertial>
    <visual>
      <origin
        xyz="0 0 0"
        rpy="0 0 0" />
      <geometry>
        <mesh
          filename="package://simple_mtm/meshes/visual/shoulder_link.STL" />
      </geometry>
      <material
        name="">
        <color
          rgba="0.752941176470588 0.752941176470588 0.752941176470588 1" />
      </material>
    </visual>
    <collision>
      <origin
        xyz="0 0 0"
        rpy="0 0 0" />
      <geometry>
        <mesh
          filename="package://simple_mtm/meshes/visual/shoulder_link.STL" />
      </geometry>
    </collision>
  </link>
  <joint
    name="shoulder_joint"
    type="continuous">
    <origin
      xyz="0 0.21528899971146 0.285000000000001"
      rpy="-1.57079632679489 0 0" />
    <parent
      link="base_link" />
    <child
      link="shoulder_link" />
    <axis
      xyz="0 0 1" />
  </joint>
  <link
    name="upper_link">
    <inertial>
      <origin
        xyz="0.113474393867847 1.3556875694265E-07 -0.00107776626147185"
        rpy="0 0 0" />
      <mass
        value="0.028442603557216" />
      <inertia
        ixx="2.23413747833826E-06"
        ixy="-3.63778375385371E-11"
        ixz="-8.63056316192405E-08"
        iyy="2.11946804960037E-05"
        iyz="1.95087355048528E-13"
        izz="2.18319915210086E-05" />
    </inertial>
    <visual>
      <origin
        xyz="0 0 0"
        rpy="0 0 0" />
      <geometry>
        <mesh
          filename="package://simple_mtm/meshes/visual/upper_link.STL" />
      </geometry>
      <material
        name="">
        <color
          rgba="0.752941176470588 0.752941176470588 0.752941176470588 1" />
      </material>
    </visual>
    <collision>
      <origin
        xyz="0 0 0"
        rpy="0 0 0" />
      <geometry>
        <mesh
          filename="package://simple_mtm/meshes/visual/upper_link.STL" />
      </geometry>
    </collision>
  </link>
  <joint
    name="upper_joint"
    type="continuous">
    <origin
      xyz="0.0450000000000016 0 0.0117110002885288"
      rpy="3.14159265358979 0 0" />
    <parent
      link="shoulder_link" />
    <child
      link="upper_link" />
    <axis
      xyz="0 1 0" />
  </joint>
  <link
    name="lower_link">
    <inertial>
      <origin
        xyz="0.0848745393470839 0.0171794620241483 -3.55317386624421E-10"
        rpy="0 0 0" />
      <mass
        value="0.0161821732101651" />
      <inertia
        ixx="8.18067052532427E-07"
        ixy="-7.46720375947648E-08"
        ixz="6.48271217616135E-14"
        iyy="1.99214030104118E-05"
        iyz="3.23675490168731E-14"
        izz="1.99376073919312E-05" />
    </inertial>
    <visual>
      <origin
        xyz="0 0 0"
        rpy="0 0 0" />
      <geometry>
        <mesh
          filename="package://simple_mtm/meshes/visual/lower_link.STL" />
      </geometry>
      <material
        name="">
        <color
          rgba="0.752941176470588 0.752941176470588 0.752941176470588 1" />
      </material>
    </visual>
    <collision>
      <origin
        xyz="0 0 0"
        rpy="0 0 0" />
      <geometry>
        <mesh
          filename="package://simple_mtm/meshes/visual/lower_link.STL" />
      </geometry>
    </collision>
  </link>
  <joint
    name="lower_join"
    type="continuous">
    <origin
      xyz="0.217499999999997 0 0"
      rpy="1.5707963267949 0 -1.5707963267949" />
    <parent
      link="upper_link" />
    <child
      link="lower_link" />
    <axis
      xyz="0 1 0" />
  </joint>
  <link
    name="gimbal_link">
    <inertial>
      <origin
        xyz="-0.0326109486090158 -0.000282236610616993 -4.57716510879752E-05"
        rpy="0 0 0" />
      <mass
        value="0.0212065913551961" />
      <inertia
        ixx="1.4925003243673E-06"
        ixy="-3.24208359028406E-08"
        ixz="-7.51135964506153E-09"
        iyy="2.56062884792426E-06"
        iyz="-7.29236206406479E-09"
        izz="2.89423672937238E-06" />
    </inertial>
    <visual>
      <origin
        xyz="0 0 0"
        rpy="0 0 0" />
      <geometry>
        <mesh
          filename="package://simple_mtm/meshes/visual/gimbal_link.STL" />
      </geometry>
      <material
        name="">
        <color
          rgba="0.752941176470588 0.752941176470588 0.752941176470588 1" />
      </material>
    </visual>
    <collision>
      <origin
        xyz="0 0 0"
        rpy="0 0 0" />
      <geometry>
        <mesh
          filename="package://simple_mtm/meshes/visual/gimbal_link.STL" />
      </geometry>
    </collision>
  </link>
  <joint
    name="gimbal_joint"
    type="continuous">
    <origin
      xyz="0.217500000000001 -0.00994999999999749 0"
      rpy="1.5707963267949 0 1.5707963267949" />
    <parent
      link="lower_link" />
    <child
      link="gimbal_link" />
    <axis
      xyz="1 0 0" />
  </joint>
  <link
    name="left_lever_link">
    <inertial>
      <origin
        xyz="0.0137564304849372 0.0128758586318367 -7.9580264641943E-08"
        rpy="0 0 0" />
      <mass
        value="0.00212674325125725" />
      <inertia
        ixx="3.06035777123236E-07"
        ixy="-3.30077722710219E-07"
        ixz="-2.03258822107502E-12"
        iyy="4.36134626560485E-07"
        iyz="-2.80091648513568E-12"
        izz="7.18020237349949E-07" />
    </inertial>
    <visual>
      <origin
        xyz="0 0 0"
        rpy="0 0 0" />
      <geometry>
        <mesh
          filename="package://simple_mtm/meshes/visual/left_lever_link.STL" />
      </geometry>
      <material
        name="">
        <color
          rgba="0.749019607843137 0.749019607843137 0.749019607843137 1" />
      </material>
    </visual>
    <collision>
      <origin
        xyz="0 0 0"
        rpy="0 0 0" />
      <geometry>
        <mesh
          filename="package://simple_mtm/meshes/visual/left_lever_link.STL" />
      </geometry>
    </collision>
  </link>
  <joint
    name="left_lever_joint"
    type="continuous">
    <origin
      xyz="-0.0593986841535711 -0.00749999999999823 0"
      rpy="3.14159265358979 0 0.279252680319092" />
    <parent
      link="gimbal_link" />
    <child
      link="left_lever_link" />
    <axis
      xyz="0 0 -1" />
  </joint>
  <link
    name="right_lever_link">
    <inertial>
      <origin
        xyz="0.0137564304849367 0.0128758586318384 -7.95802654607325E-08"
        rpy="0 0 0" />
      <mass
        value="0.00212674325125726" />
      <inertia
        ixx="3.06035777123239E-07"
        ixy="-3.30077722710219E-07"
        ixz="-2.03258822001266E-12"
        iyy="4.36134626560484E-07"
        iyz="-2.80091648406903E-12"
        izz="7.1802023734995E-07" />
    </inertial>
    <visual>
      <origin
        xyz="0 0 0"
        rpy="0 0 0" />
      <geometry>
        <mesh
          filename="package://simple_mtm/meshes/visual/right_lever_link.STL" />
      </geometry>
      <material
        name="">
        <color
          rgba="0.749019607843137 0.749019607843137 0.749019607843137 1" />
      </material>
    </visual>
    <collision>
      <origin
        xyz="0 0 0"
        rpy="0 0 0" />
      <geometry>
        <mesh
          filename="package://simple_mtm/meshes/visual/right_lever_link.STL" />
      </geometry>
    </collision>
  </link>
  <joint
    name="right_lever_joint"
    type="continuous">
    <origin
      xyz="-0.0593986841535731 0.00750000000000245 0"
      rpy="0 0 -0.279252680319087" />
    <parent
      link="gimbal_link" />
    <child
      link="right_lever_link" />
    <axis
      xyz="0 0 1" />
  </joint>
</robot>