<sdf version="1.7">
  <model name="simple_PSM">
    <link name="base_link">
      <inertial>
        <pose>-3e-06 0.086287 -0.069925 0 -0 0</pose>
        <mass>2.08419</mass>
        <inertia>
          <ixx>0.0128141</ixx>
          <ixy>1.93105e-07</ixy>
          <ixz>-3.28129e-08</ixz>
          <iyy>0.0117487</iyy>
          <iyz>-2.76942e-06</iyz>
          <izz>0.00436365</izz>
        </inertia>
      </inertial>
      <collision name="base_link_collision">
        <pose>0 0 0 0 -0 0</pose>
        <geometry>
          <mesh>
            <scale>1 1 1</scale>
            <uri>package://simple_psm/meshes/visual/base_link.STL</uri>
          </mesh>
        </geometry>
      </collision>
      <visual name="base_link_visual">
        <pose>0 0 0 0 -0 0</pose>
        <geometry>
          <mesh>
            <scale>1 1 1</scale>
            <uri>package://simple_psm/meshes/visual/base_link.STL</uri>
          </mesh>
        </geometry>
      </visual>
    </link>
    <joint name="roller_joint" type="revolute">
      <pose relative_to="base_link">0 0 0.2733 -3.14159 -0 1.5708</pose>
      <parent>base_link</parent>
      <child>roller_link</child>
      <axis>
        <xyz>-1 0 0</xyz>
        <limit>
          <lower>-1e+16</lower>
          <upper>1e+16</upper>
        </limit>
        <dynamics>
          <spring_reference>0</spring_reference>
          <spring_stiffness>0</spring_stiffness>
        </dynamics>
      </axis>
    </joint>
    <link name="roller_link">
      <pose relative_to="roller_joint">0 0 0 0 -0 0</pose>
      <inertial>
        <pose>-0.04155 0.00364 0.016055 0 -0 0</pose>
        <mass>0.874974</mass>
        <inertia>
          <ixx>0.00170996</ixx>
          <ixy>-1.76481e-06</ixy>
          <ixz>1.76187e-06</ixz>
          <iyy>0.00154081</iyy>
          <iyz>4.31194e-06</iyz>
          <izz>0.00212538</izz>
        </inertia>
      </inertial>
      <collision name="roller_link_collision">
        <pose>0 0 0 0 -0 0</pose>
        <geometry>
          <mesh>
            <scale>1 1 1</scale>
            <uri>package://simple_psm/meshes/visual/roller_link.STL</uri>
          </mesh>
        </geometry>
      </collision>
      <visual name="roller_link_visual">
        <pose>0 0 0 0 -0 0</pose>
        <geometry>
          <mesh>
            <scale>1 1 1</scale>
            <uri>package://simple_psm/meshes/visual/roller_link.STL</uri>
          </mesh>
        </geometry>
      </visual>
    </link>
    <joint name="long_joint" type="revolute">
      <pose relative_to="roller_link">-0.1655 0 0 -1.5708 -0.46639 0</pose>
      <parent>roller_link</parent>
      <child>long_link</child>
      <axis>
        <xyz>0 0 1</xyz>
        <limit>
          <lower>-1e+16</lower>
          <upper>1e+16</upper>
        </limit>
        <dynamics>
          <spring_reference>0</spring_reference>
          <spring_stiffness>0</spring_stiffness>
        </dynamics>
      </axis>
    </joint>
    <link name="long_link">
      <pose relative_to="long_joint">0 0 0 0 -0 0</pose>
      <inertial>
        <pose>0.026461 0.108425 0.003 0 -0 0</pose>
        <mass>0.208754</mass>
        <inertia>
          <ixx>0.000719637</ixx>
          <ixy>-0.000227238</ixy>
          <ixz>-1.48027e-16</ixz>
          <iyy>0.000100218</iyy>
          <iyz>-1.83931e-17</iyz>
          <izz>0.000810089</izz>
        </inertia>
      </inertial>
      <collision name="long_link_collision">
        <pose>0 0 0 0 -0 0</pose>
        <geometry>
          <mesh>
            <scale>1 1 1</scale>
            <uri>package://simple_psm/meshes/visual/long_link.STL</uri>
          </mesh>
        </geometry>
      </collision>
      <visual name="long_link_visual">
        <pose>0 0 0 0 -0 0</pose>
        <geometry>
          <mesh>
            <scale>1 1 1</scale>
            <uri>package://simple_psm/meshes/visual/long_link.STL</uri>
          </mesh>
        </geometry>
      </visual>
    </link>
    <joint name="lower_arm_join" type="fixed">
      <pose relative_to="long_link">-0.12393 0.053006 0.003 -2.67454 -1.57079 -3.14159</pose>
      <parent>long_link</parent>
      <child>lower_arm_link</child>
      <axis>
        <xyz>0 0 1</xyz>
        <limit>
          <lower>-1e+16</lower>
          <upper>1e+16</upper>
        </limit>
        <dynamics>
          <spring_reference>0</spring_reference>
          <spring_stiffness>0</spring_stiffness>
        </dynamics>
      </axis>
    </joint>
    <link name="lower_arm_link">
      <pose relative_to="lower_arm_join">0 0 0 0 -0 0</pose>
      <inertial>
        <pose>-0 -0.009611 0.046684 0 -0 0</pose>
        <mass>0.181539</mass>
        <inertia>
          <ixx>0.000458934</ixx>
          <ixy>-3.57098e-13</ixy>
          <ixz>-2.70293e-11</ixz>
          <iyy>0.000578512</iyy>
          <iyz>1.63821e-06</iyz>
          <izz>0.000132062</izz>
        </inertia>
      </inertial>
      <collision name="lower_arm_link_collision">
        <pose>0 0 0 0 -0 0</pose>
        <geometry>
          <mesh>
            <scale>1 1 1</scale>
            <uri>package://simple_psm/meshes/visual/lower_arm_link.STL</uri>
          </mesh>
        </geometry>
      </collision>
      <visual name="lower_arm_link_visual">
        <pose>0 0 0 0 -0 0</pose>
        <geometry>
          <mesh>
            <scale>1 1 1</scale>
            <uri>package://simple_psm/meshes/visual/lower_arm_link.STL</uri>
          </mesh>
        </geometry>
      </visual>
    </link>
    <joint name="upper_arm_joint" type="fixed">
      <pose relative_to="long_link">-0.12393 0.12301 0.003 -2.67454 -1.57079 -3.14159</pose>
      <parent>long_link</parent>
      <child>upper_arm_link</child>
      <axis>
        <xyz>0 0 1</xyz>
        <limit>
          <lower>-1e+16</lower>
          <upper>1e+16</upper>
        </limit>
        <dynamics>
          <spring_reference>0</spring_reference>
          <spring_stiffness>0</spring_stiffness>
        </dynamics>
      </axis>
    </joint>
    <link name="upper_arm_link">
      <pose relative_to="upper_arm_joint">0 0 0 0 -0 0</pose>
      <inertial>
        <pose>-0 -0.009611 0.046684 0 -0 0</pose>
        <mass>0.181539</mass>
        <inertia>
          <ixx>0.000458934</ixx>
          <ixy>-3.57098e-13</ixy>
          <ixz>-2.70293e-11</ixz>
          <iyy>0.000578512</iyy>
          <iyz>1.63821e-06</iyz>
          <izz>0.000132062</izz>
        </inertia>
      </inertial>
      <collision name="upper_arm_link_collision">
        <pose>0 0 0 0 -0 0</pose>
        <geometry>
          <mesh>
            <scale>1 1 1</scale>
            <uri>package://simple_psm/meshes/visual/upper_arm_link.STL</uri>
          </mesh>
        </geometry>
      </collision>
      <visual name="upper_arm_link_visual">
        <pose>0 0 0 0 -0 0</pose>
        <geometry>
          <mesh>
            <scale>1 1 1</scale>
            <uri>package://simple_psm/meshes/visual/upper_arm_link.STL</uri>
          </mesh>
        </geometry>
      </visual>
    </link>
    <joint name="head_joint" type="fixed">
      <pose relative_to="upper_arm_link">-0.042836 0.077429 -0.051146 -1.5708 -0.46705 -1.5708</pose>
      <parent>upper_arm_link</parent>
      <child>head_link</child>
      <axis>
        <xyz>0 0 1</xyz>
        <limit>
          <lower>-1e+16</lower>
          <upper>1e+16</upper>
        </limit>
        <dynamics>
          <spring_reference>0</spring_reference>
          <spring_stiffness>0</spring_stiffness>
        </dynamics>
      </axis>
    </joint>
    <link name="head_link">
      <pose relative_to="head_joint">0 0 0 0 -0 0</pose>
      <inertial>
        <pose>0.164239 0.066585 0.042736 0 -0 0</pose>
        <mass>1.08894</mass>
        <inertia>
          <ixx>0.000898013</ixx>
          <ixy>9.69778e-06</ixy>
          <ixz>1.35176e-06</ixz>
          <iyy>0.00866635</iyy>
          <iyz>-7.56506e-07</iyz>
          <izz>0.00801157</izz>
        </inertia>
      </inertial>
      <collision name="head_link_collision">
        <pose>0 0 0 0 -0 0</pose>
        <geometry>
          <mesh>
            <scale>1 1 1</scale>
            <uri>package://simple_psm/meshes/visual/head_link.STL</uri>
          </mesh>
        </geometry>
      </collision>
      <visual name="head_link_visual">
        <pose>0 0 0 0 -0 0</pose>
        <geometry>
          <mesh>
            <scale>1 1 1</scale>
            <uri>package://simple_psm/meshes/visual/head_link.STL</uri>
          </mesh>
        </geometry>
      </visual>
    </link>
    <joint name="sled_joint" type="prismatic">
      <pose relative_to="head_link">0 0.066487 0.042836 0 -0 0</pose>
      <parent>head_link</parent>
      <child>sled_link</child>
      <axis>
        <xyz>1 0 0</xyz>
        <limit>
          <lower>0</lower>
          <upper>0</upper>
          <effort>0</effort>
          <velocity>0</velocity>
        </limit>
        <dynamics>
          <spring_reference>0</spring_reference>
          <spring_stiffness>0</spring_stiffness>
        </dynamics>
      </axis>
    </joint>
    <link name="sled_link">
      <pose relative_to="sled_joint">0 0 0 0 -0 0</pose>
      <inertial>
        <pose>0.265732 0.040173 -0.000151 0 -0 0</pose>
        <mass>0.542497</mass>
        <inertia>
          <ixx>0.000163983</ixx>
          <ixy>1.70355e-06</ixy>
          <ixz>1.53006e-06</ixz>
          <iyy>0.00213319</iyy>
          <iyz>1.64197e-08</iyz>
          <izz>0.00201456</izz>
        </inertia>
      </inertial>
      <collision name="sled_link_collision">
        <pose>0 0 0 0 -0 0</pose>
        <geometry>
          <mesh>
            <scale>1 1 1</scale>
            <uri>package://simple_psm/meshes/visual/sled_link.STL</uri>
          </mesh>
        </geometry>
      </collision>
      <visual name="sled_link_visual">
        <pose>0 0 0 0 -0 0</pose>
        <geometry>
          <mesh>
            <scale>1 1 1</scale>
            <uri>package://simple_psm/meshes/visual/sled_link.STL</uri>
          </mesh>
        </geometry>
      </visual>
    </link>
    <joint name="short_joint" type="revolute">
      <pose relative_to="roller_link">-0.2655 0 0 -1.5708 0.7854 -3.14159</pose>
      <parent>roller_link</parent>
      <child>short_link</child>
      <axis>
        <xyz>0 0 -1</xyz>
        <limit>
          <lower>-1e+16</lower>
          <upper>1e+16</upper>
        </limit>
        <dynamics>
          <spring_reference>0</spring_reference>
          <spring_stiffness>0</spring_stiffness>
        </dynamics>
      </axis>
    </joint>
    <link name="short_link">
      <pose relative_to="short_joint">0 0 0 0 -0 0</pose>
      <inertial>
        <pose>-0 0.082299 -0.003 0 -0 0</pose>
        <mass>0.0886392</mass>
        <inertia>
          <ixx>0.000213866</ixx>
          <ixy>5.23466e-19</ixy>
          <ixz>-1.47e-21</ixz>
          <iyy>5.6089e-06</iyy>
          <iyz>-2.30724e-19</iyz>
          <izz>0.000217615</izz>
        </inertia>
      </inertial>
      <collision name="short_link_collision">
        <pose>0 0 0 0 -0 0</pose>
        <geometry>
          <mesh>
            <scale>1 1 1</scale>
            <uri>package://simple_psm/meshes/visual/short_link.STL</uri>
          </mesh>
        </geometry>
      </collision>
      <visual name="short_link_visual">
        <pose>0 0 0 0 -0 0</pose>
        <geometry>
          <mesh>
            <scale>1 1 1</scale>
            <uri>package://simple_psm/meshes/visual/short_link.STL</uri>
          </mesh>
        </geometry>
      </visual>
    </link>
  </model>
</sdf>